"use client";

import React from "react";
import { Card, CardHeader, CardTitle, CardContent } from "@/components/ui/card";
import { Button } from "@/components/ui/button";

interface ErrorBoundaryState {
  hasError: boolean;
  error?: Error;
}

interface ErrorBoundaryProps {
  children: React.ReactNode;
  fallback?: React.ComponentType<{ error: Error; retry: () => void }>;
}

export class ErrorBoundary extends React.Component<ErrorBoundaryProps, ErrorBoundaryState> {
  constructor(props: ErrorBoundaryProps) {
    super(props);
    this.state = { hasError: false };
  }

  static getDerivedStateFromError(error: Error): ErrorBoundaryState {
    return { hasError: true, error };
  }

  componentDidCatch(error: Error, errorInfo: React.ErrorInfo) {
    console.error('Error caught by boundary:', error, errorInfo);
  }

  retry = () => {
    this.setState({ hasError: false, error: undefined });
  };

  render() {
    if (this.state.hasError) {
      if (this.props.fallback) {
        const Fallback = this.props.fallback;
        return <Fallback error={this.state.error!} retry={this.retry} />;
      }

      return <DefaultErrorFallback error={this.state.error!} retry={this.retry} />;
    }

    return this.props.children;
  }
}

// Default error fallback component
function DefaultErrorFallback({ error, retry }: { error: Error; retry: () => void }) {
  return (
    <Card className="p-6">
      <CardHeader>
        <CardTitle className="text-red-600">Something went wrong</CardTitle>
      </CardHeader>
      <CardContent className="space-y-4">
        <p className="text-muted-foreground">
          {error.message || "An unexpected error occurred"}
        </p>
        <Button onClick={retry} variant="outline">
          Try again
        </Button>
      </CardContent>
    </Card>
  );
}

// Hook-based error boundary for functional components
export function useErrorHandler() {
  const [error, setError] = React.useState<Error | null>(null);

  const resetError = () => setError(null);

  const handleError = React.useCallback((error: Error) => {
    console.error('Error handled:', error);
    setError(error);
  }, []);

  if (error) {
    throw error; // This will be caught by the nearest ErrorBoundary
  }

  return { handleError, resetError };
} 